<?xml version ="1.0"?>
<sdf version="1.6">
    <model name="excavation_square_x">
        <static>false</static>
        <link name="excavation_square_x_base_link">
            <collision name="excavation_square_x_1_collision_1">
                <pose>0 0 0 0 0 0</pose>
                <geometry>
                    <box>
                        <size>0.185 0.015 0.07</size>
                    </box>
                </geometry>
            </collision>
            <collision name="excavation_square_x_1_collision_2">
                <pose>0.085 -0.035 0 0 0 0</pose>
                <geometry>
                    <box>
                        <size>0.015 0.055 0.07</size>
                    </box>
                </geometry>
            </collision>
            <collision name="excavation_suqare_x_1_collision_3">
                <pose>-0.085  -0.035 0 0 0 0</pose>
                <geometry>
                    <box>
                        <size>0.015 0.055 0.07</size>
                    </box>
                </geometry>
            </collision>
            <inertial>
                <inertia>
                    <ixx>0.01</ixx>
                    <ixy>0</ixy>
                    <ixz>0</ixz>
                    <iyy>0.01</iyy>
                    <iyz>0</iyz>
                    <izz>0.01</izz>
                </inertia>
                <mass>0.1</mass>
            </inertial>
            <visual name="excavation_square_x_1_visual_1">
                <pose>0 0 0 0 0 0</pose>
                <geometry>
                    <box>
                        <size>0.185 0.015 0.07</size>
                    </box>
                </geometry>
                <material>
                    <ambient>0.71 0.69 0.63 1.0</ambient>
                    <diffuse>0.71 0.69 0.63 1.0</diffuse>
                    <specular>0.1 0.1 0.1 1</specular>
                    <emissive>0 0 0 0</emissive>
                </material> 
            </visual>
            <visual name="excavation_square_x_1_visual_2">
                <pose>0.085 -0.035 0 0 0 0</pose>
                <geometry>
                    <box>
                        <size>0.015 0.055 0.07</size>
                    </box>
                </geometry>
                <material>
                    <ambient>0.71 0.69 0.63 1.0</ambient>
                    <diffuse>0.71 0.69 0.63 1.0</diffuse>
                    <specular>0.1 0.1 0.1 1</specular>
                    <emissive>0 0 0 0</emissive>
                </material> 
            </visual>
            <visual name="excavation_square_x_1_visual_3">
                <pose>-0.085 -0.035 0 0 0 0</pose>
                <geometry>
                    <box>
                        <size>0.015 0.055 0.07</size>
                    </box>
                </geometry>
                <material>
                    <ambient>0.71 0.69 0.63 1.0</ambient>
                    <diffuse>0.71 0.69 0.63 1.0</diffuse>
                    <specular>0.1 0.1 0.1 1</specular>
                    <emissive>0 0 0 0</emissive>
                </material> 
            </visual>
        </link>
        <link name="excavation_square_x_image_holder">
            <pose>0 -0.0235 0.044 2.74016692563 0 0</pose>
            <collision name="excavation_square_x_image_holder_collision">
                <geometry>
                    <box>
                        <size>0.15 0.02 0.15</size>
                    </box>
                </geometry>
            </collision>
            <inertial>
                <inertia>
                    <ixx>0.01</ixx>
                    <ixy>0</ixy>
                    <ixz>0</ixz>
                    <iyy>0.01</iyy>
                    <iyz>0</iyz>
                    <izz>0.01</izz>
                </inertia>
                <mass>0.1</mass>
            </inertial>
            <visual name="excavation_square_x_image_holder_visual">
                <geometry>
                    <box>
                        <size>0.15 0.02 0.15</size>
                    </box>
                </geometry>
                <material>
                    <ambient>0.71 0.69 0.63 1.0</ambient>
                    <diffuse>0.71 0.69 0.63 1.0</diffuse>
                    <specular>0.1 0.1 0.1 1</specular>
                    <emissive>0 0 0 0</emissive>
                </material>
            </visual>
            <visual name="excavation_square_x_image_holder_texture">
                <pose>0 -0.01001 0 0 0 0</pose>
                <geometry>
                    <box>
                        <size>0.15 0.0001 0.15</size>
                    </box>
                </geometry>
                <material>
                    <ambient>1 1 1 1</ambient>
                    <diffuse>1 1 1 1</diffuse>
                    <specular>0.1 0.1 0.1 1</specular>
                    <pbr>
                        <metal>
                            <albedo_map>materials/textures/vinyle_excavation_x.png</albedo_map>
                            <roughness>1.0</roughness>
                            <metalness>0.0</metalness>
                        </metal>
                    </pbr>
                </material>
            </visual>

        </link>
        <joint name="image_holder_revolute" type="revolute">
            <parent>excavation_square_x_base_link</parent>
            <child>excavation_square_x_image_holder</child>
            <pose>0 0 0.07 0 0 0</pose>
            <axis>
                <xyz>1 0 0</xyz>
                <dynamics>
                    <damping>0.02</damping>
                </dynamics>
            </axis>
        </joint>
        <joint name="base_to_world" type="fixed">
            <parent>world</parent>
            <child>excavation_square_x_base_link</child>
            <pose>0 0 0 0 0 0</pose>
        </joint>
    </model>
</sdf>